<?xml version="1.0"?>

<robot xmlns:xacro="http://www.ros.org/wiki/xacro">

    <xacro:include filename="inertial_macros.xacro"/>

  <xacro:macro name="mecanum_wheel" params="prefix color *origin *axis">
    <joint name="${prefix}_wheel_joint" type="continuous">
      <xacro:insert_block name="origin"/>
      <parent link="${prefix}"/>
      <child link="${prefix}_roller"/>
      <xacro:insert_block name="axis"/>
    </joint>

    <link name="${prefix}">
      <visual>
        <geometry>
          <cylinder radius="0.1" length="0.04"/>
        </geometry>
        <material name="${color}"/>
      </visual>

      <collision>
        <geometry>
          <cylinder radius="0.1" length="0.04"/>
        </geometry>
      </collision>

        <xacro:inertial_cylinder mass="0.05" length="0.04" radius="0.1">
            <origin xyz="0 0 0" rpy="0 0 0"/>
        </xacro:inertial_cylinder>

    </link>

    <gazebo reference="${prefix}">
        <material>
            Gazebo/Black            
        </material>
    </gazebo>


    <link name="${prefix}_roller">
      <visual>
        <geometry>
          <cylinder radius="0.06" length="0.007"/>
        </geometry>
        <material name="${color}"/>
      </visual>

      <collision>
        <geometry>
          <cylinder radius="0.06" length="0.007"/>
        </geometry>
      </collision>

    <xacro:inertial_cylinder mass="0.001" length="0.0008" radius="0.002">
            <origin xyz="0 0 0" rpy="0 0 0"/>
        </xacro:inertial_cylinder>

    </link>

    <gazebo reference="${prefix}_roller">
        <material>
            Gazebo/Orange          
        </material>
    </gazebo>

  </xacro:macro>

</robot>